<!-- Converted from urdf with urdf2mjcf -->
<!-- Model edited by Jessica Anz -->

<mujoco model="cat">
  <option iterations="50" timestep="0.001" solver="PGS" gravity="0 0 -9.81" />

  <compiler angle="radian" meshdir="meshes" eulerseq="zyx" autolimits="true" />

  <default>
    <joint limited="true" damping="0.01" armature="0.01" frictionloss="0.01" />
    <geom condim="4" contype="1" conaffinity="15" friction="0.9 0.2 0.2" solref="0.001 2" />
    <motor ctrllimited="true" />
    <equality solref="0.001 2" />
    <default class="visualgeom">
      <geom material="visualgeom" condim="1" contype="0" conaffinity="0" />
    </default>
  </default>

  <asset>
    <mesh name="base_link" content_type="model/stl" file="base_link.STL" />
    <mesh name="upperleg_fl" content_type="model/stl" file="upperleg_fl.STL" />
    <mesh name="lowerleg_fl" content_type="model/stl" file="lowerleg_fl.STL" />
    <mesh name="upperleg_fr" content_type="model/stl" file="upperleg_fr.STL" />
    <mesh name="lowerleg_fr" content_type="model/stl" file="lowerleg_fr.STL" />
    <mesh name="upperleg_bl" content_type="model/stl" file="upperleg_bl.STL" />
    <mesh name="lowerleg_bl" content_type="model/stl" file="lowerleg_bl.STL" />
    <mesh name="upperleg_br" content_type="model/stl" file="upperleg_br.STL" />
    <mesh name="lowerleg_br" content_type="model/stl" file="lowerleg_br.STL" />
    <texture name="texplane" type="2d" builtin="checker" rgb1="0.2 0.3 0.4" rgb2="0.1 0.2 0.3" width="100" height="100" />
    <material name="matplane" reflectance="0." texture="texplane" texrepeat="1 1" texuniform="true" />
    <material name="visualgeom" rgba="0.5 0.9 0.2 1" />
  </asset>

  <worldbody>
    <light directional="true" diffuse="0.4 0.4 0.4" specular="0.1 0.1 0.1" pos="0 0 5.0" dir="0 0 -1" castshadow="false" />
    <light directional="true" diffuse="0.6 0.6 0.6" specular="0.2 0.2 0.2" pos="0 0 4" dir="0 0 -1" />
    <geom name="ground" type="plane" pos="0 0 0" size="100 100 0.001" quat="1 0 0 0" material="matplane" condim="3" conaffinity="15" />
    <camera name="fixed" pos="0 -3.0 -0.09580315099662151" xyaxes="1 0 0 0 0 1" />
    <camera name="track" mode="trackcom" pos="0 -3.0 -0.09580315099662151" xyaxes="1 0 0 0 0 1" />
    <body name="root" pos="0 0 -0.5958031509966215" quat="1 0 0 0">
      <freejoint name="root" />
      <geom type="mesh" rgba="0.79216 0.81961 0.93333 1" mesh="base_link" contype="1" conaffinity="0" density="0" group="1" class="visualgeom" />
      <geom type="mesh" rgba="0.79216 0.81961 0.93333 1" mesh="base_link" />

      <body name="upperleg_fl" pos="0.72627 -1.3017 0.72616" quat="0.377866 2.0129e-06 0.92586 2.0129e-06">
        <inertial pos="0.024758 -0.02325 0.024007" quat="0.275621 0.27562 -0.651178 0.651178" mass="0.060463" diaginertia="1.94562e-05 1.45858e-05 1.3106e-05" />
        <joint name="hip_fl" pos="0 0 0" axis="0 1 0" range="-1.57 1.57" />
        <geom type="mesh" rgba="0.79216 0.81961 0.93333 1" mesh="upperleg_fl" contype="1" conaffinity="0" density="0" group="1" class="visualgeom" />
        <geom type="mesh" rgba="0.79216 0.81961 0.93333 1" mesh="upperleg_fl" />
        <body name="lowerleg_fl" pos="0.039486 0 0.038287" quat="-3.40178e-06 0.377264 1.38577e-06 0.926106">
          <inertial pos="-4.75474e-09 0.02325 0.0364632" quat="1 -7.49515e-07 3.35811e-12 -4.48038e-06" mass="0.0699581" diaginertia="3.15837e-05 2.19759e-05 1.91147e-05" />
          <joint name="knee_fl" pos="0 0 0" axis="0 1 0" range="-1.57 1.57" />
          <geom type="mesh" rgba="0.792157 0.819608 0.933333 1" mesh="lowerleg_fl" contype="1" conaffinity="0" density="0" group="1" class="visualgeom" />
          <geom type="mesh" rgba="0.792157 0.819608 0.933333 1" mesh="lowerleg_fl" />
          <geom name="foot_fl" type="cylinder" size="0.015 0.02" pos="0 0.024 0.051" contype="1" conaffinity="1" friction="1.0 0.2 0.1" quat="0.707 0.707 0 0"/>
        </body>
      </body>

      <body name="upperleg_fr" pos="0.72627 -1.2165 0.72616" quat="0.388294 1.9587e-06 0.921535 1.9587e-06">
        <inertial pos="0.024758 -0.02325 0.024007" quat="0.275621 0.27562 -0.651178 0.651178" mass="0.060463" diaginertia="1.94562e-05 1.45858e-05 1.3106e-05" />
        <joint name="hip_fr" pos="0 0 0" axis="0 1 0" range="-1.57 1.57" />
        <geom type="mesh" rgba="0.79216 0.81961 0.93333 1" mesh="upperleg_fr" contype="1" conaffinity="0" density="0" group="1" class="visualgeom" />
        <geom type="mesh" rgba="0.79216 0.81961 0.93333 1" mesh="upperleg_fr" />
        <body name="lowerleg_fr" pos="0.039486 0 0.038287" quat="-3.37493e-06 0.394731 1.44993e-06 0.918797">
          <inertial pos="-4.43034e-09 0.02325 0.0364632" quat="1 -8.27384e-07 3.70883e-12 -4.4826e-06" mass="0.0699581" diaginertia="3.15837e-05 2.19759e-05 1.91147e-05" />
          <joint name="knee_fr" pos="0 0 0" axis="0 1 0" range="-1.57 1.57" />
          <geom type="mesh" rgba="0.792157 0.819608 0.933333 1" mesh="lowerleg_fr" contype="1" conaffinity="0" density="0" group="1" class="visualgeom" />
          <geom type="mesh" rgba="0.792157 0.819608 0.933333 1" mesh="lowerleg_fr" />
          <geom name="foot_fr" type="cylinder" size="0.015 0.02" pos="0 0.024 0.051" contype="1" conaffinity="1" friction="1.0 0.2 0.1" quat="0.707 0.707 0 0"/>
        </body>
      </body>

      <body name="upperleg_bl" pos="0.55677 -1.3166 0.72616" quat="-3.64141e-06 0.991343 4.82291e-07 0.1313">
        <inertial pos="-0.00976295 0.0232502 0.0342534" quat="0.700479 0.700472 -0.0966121 0.0966111" mass="0.0573353" diaginertia="1.79861e-05 1.30651e-05 1.20634e-05" />
        <joint name="hip_bl" pos="0 0 0" axis="0 1 0" range="-1.57 1.57" />
        <geom type="mesh" rgba="0.792157 0.819608 0.933333 1" mesh="upperleg_bl" contype="1" conaffinity="0" density="0" group="1" class="visualgeom" />
        <geom type="mesh" rgba="0.792157 0.819608 0.933333 1" mesh="upperleg_bl" />
        <body name="lowerleg_bl" pos="-0.015108 0 0.052884" quat="0.990733 0 -0.135824 0">
          <inertial pos="-4.50047e-09 0.02325 0.0364632" quat="1 -8.09409e-07 3.62809e-12 -4.48239e-06" mass="0.0699581" diaginertia="3.15837e-05 2.19759e-05 1.91147e-05" />
          <joint name="knee_bl" pos="0 0 0" axis="0 1 0" range="-1.57 1.57" />
          <geom type="mesh" rgba="0.792157 0.819608 0.933333 1" mesh="lowerleg_bl" contype="1" conaffinity="0" density="0" group="1" class="visualgeom" />
          <geom type="mesh" rgba="0.792157 0.819608 0.933333 1" mesh="lowerleg_bl" />
          <geom name="foot_bl" type="cylinder" size="0.015 0.02" pos="0 0.024 0.051" contype="1" conaffinity="1" friction="1.0 0.2 0.1" quat="0.707 0.707 0 0"/>
        </body>
      </body>

      <body name="upperleg_br" pos="0.55677 -1.2016 0.72616" quat="-3.63807e-06 -0.990435 5.06823e-07 -0.137978">
        <inertial pos="-0.00976295 0.0232502 0.0342534" quat="0.700479 0.700472 -0.0966121 0.0966111" mass="0.0573353" diaginertia="1.79861e-05 1.30651e-05 1.20634e-05" />
        <joint name="hip_br" pos="0 0 0" axis="0 1 0" range="-1.57 1.57" />
        <geom type="mesh" rgba="0.792157 0.819608 0.933333 1" mesh="upperleg_br" contype="1" conaffinity="0" density="0" group="1" class="visualgeom" />
        <geom type="mesh" rgba="0.792157 0.819608 0.933333 1" mesh="upperleg_br" />
        <body name="lowerleg_br" pos="-0.015108 0 0.052884" quat="0.988852 0 -0.148904 0">
          <inertial pos="-4.47947e-09 0.02325 0.0364632" quat="1 -8.14809e-07 3.65234e-12 -4.48245e-06" mass="0.0699581" diaginertia="3.15837e-05 2.19759e-05 1.91147e-05" />
          <joint name="knee_br" pos="0 0 0" axis="0 1 0" range="-1.57 1.57" />
          <geom type="mesh" rgba="0.792157 0.819608 0.933333 1" mesh="lowerleg_br" contype="1" conaffinity="0" density="0" group="1" class="visualgeom" />
          <geom type="mesh" rgba="0.792157 0.819608 0.933333 1" mesh="lowerleg_br" />
          <geom name="foot_br" type="cylinder" size="0.015 0.02" pos="0 0.024 0.051" contype="1" conaffinity="1" friction="1.0 0.2 0.1" quat="0.707 0.707 0 0"/>
        </body>
      </body>

    </body>
  </worldbody>

  <actuator>
    <motor name="hip_fl" joint="hip_fl" ctrllimited="true" ctrlrange="-1 1" gear="100" />
    <motor name="knee_fl" joint="knee_fl" ctrllimited="true" ctrlrange="-1 1" gear="100" />
    <motor name="hip_fr" joint="hip_fr" ctrllimited="true" ctrlrange="-1 1" gear="100" />
    <motor name="knee_fr" joint="knee_fr" ctrllimited="true" ctrlrange="-1 1" gear="100" />
    <motor name="hip_bl" joint="hip_bl" ctrllimited="true" ctrlrange="-1 1" gear="100" />
    <motor name="knee_bl" joint="knee_bl" ctrllimited="true" ctrlrange="-1 1" gear="100" />
    <motor name="hip_br" joint="hip_br" ctrllimited="true" ctrlrange="-1 1" gear="100" />
    <motor name="knee_br" joint="knee_br" ctrllimited="true" ctrlrange="-1 1" gear="100" />
  </actuator>

  <sensor>
    <actuatorpos name="hip_fl_p" actuator="hip_fl" />
    <actuatorvel name="hip_fl_v" actuator="hip_fl" />
    <actuatorfrc name="hip_fl_f" actuator="hip_fl" noise="0.001" />
    <actuatorpos name="knee_fl_p" actuator="knee_fl" />
    <actuatorvel name="knee_fl_v" actuator="knee_fl" />
    <actuatorfrc name="knee_fl_f" actuator="knee_fl" noise="0.001" />
    <actuatorpos name="hip_fr_p" actuator="hip_fr" />
    <actuatorvel name="hip_fr_v" actuator="hip_fr" />
    <actuatorfrc name="hip_fr_f" actuator="hip_fr" noise="0.001" />
    <actuatorpos name="knee_fr_p" actuator="knee_fr" />
    <actuatorvel name="knee_fr_v" actuator="knee_fr" />
    <actuatorfrc name="knee_fr_f" actuator="knee_fr" noise="0.001" />
    <actuatorpos name="hip_bl_p" actuator="hip_bl" />
    <actuatorvel name="hip_bl_v" actuator="hip_bl" />
    <actuatorfrc name="hip_bl_f" actuator="hip_bl" noise="0.001" />
    <actuatorpos name="knee_bl_p" actuator="knee_bl" />
    <actuatorvel name="knee_bl_v" actuator="knee_bl" />
    <actuatorfrc name="knee_bl_f" actuator="knee_bl" noise="0.001" />
    <actuatorpos name="hip_br_p" actuator="hip_br" />
    <actuatorvel name="hip_br_v" actuator="hip_br" />
    <actuatorfrc name="hip_br_f" actuator="hip_br" noise="0.001" />
    <actuatorpos name="knee_br_p" actuator="knee_br" />
    <actuatorvel name="knee_br_v" actuator="knee_br" />
    <actuatorfrc name="knee_br_f" actuator="knee_br" noise="0.001" />
  </sensor>
</mujoco>