<?xml version="1.0" encoding="utf-8"?>
<!-- This URDF was automatically created by SolidWorks to URDF Exporter! Originally created by Stephen Brawner (brawner@gmail.com) 
     Commit Version: 1.6.0-4-g7f85cfe  Build Version: 1.6.7995.38578
     For more information, please see http://wiki.ros.org/sw_urdf_exporter -->
<robot
  name="cat">
  <link
    name="base_link">
    <inertial>
      <origin
        xyz="0.64764 0.82118 1.2823"
        rpy="0 0 0" />
      <mass
        value="1.1099" />
      <inertia
        ixx="0.0017323"
        ixy="9.498E-05"
        ixz="-1.8477E-07"
        iyy="0.0066445"
        iyz="-4.1769E-07"
        izz="0.0058051" />
    </inertial>
    <visual>
      <origin
        xyz="0 0 0"
        rpy="0 0 0" />
      <geometry>
        <mesh
          filename="../meshes/base_link.STL" />
      </geometry>
      <material
        name="">
        <color
          rgba="0.79216 0.81961 0.93333 1" />
      </material>
    </visual>
    <collision>
      <origin
        xyz="0 0 0"
        rpy="0 0 0" />
      <geometry>
        <mesh
          filename="../meshes/base_link.STL" />
      </geometry>
    </collision>
  </link>
  <link
    name="upperleg_fl">
    <inertial>
      <origin
        xyz="0.024758 -0.02325 0.024007"
        rpy="0 0 0" />
      <mass
        value="0.060463" />
      <inertia
        ixx="1.6946E-05"
        ixy="-6.5718E-12"
        ixz="-2.434E-06"
        iyy="1.3106E-05"
        iyz="7.5191E-12"
        izz="1.7096E-05" />
    </inertial>
    <visual>
      <origin
        xyz="0 0 0"
        rpy="0 0 0" />
      <geometry>
        <mesh
          filename="../meshes/upperleg_fl.STL" />
      </geometry>
      <material
        name="">
        <color
          rgba="0.79216 0.81961 0.93333 1" />
      </material>
    </visual>
    <collision>
      <origin
        xyz="0 0 0"
        rpy="0 0 0" />
      <geometry>
        <mesh
          filename="../meshes/upperleg_fl.STL" />
      </geometry>
    </collision>
  </link>
  <joint
    name="hip_fl"
    type="revolute">
    <origin
      xyz="0.72627 -1.3017 0.72616"
      rpy="-3.1416 0.77498 -3.1416" />
    <parent
      link="base_link" />
    <child
      link="upperleg_fl" />
    <axis
      xyz="0 1 0" />
    <limit
      lower="-1.57"
      upper="1.57"
      effort="0"
      velocity="0" />
  </joint>
  <link
    name="lowerleg_fl">
    <inertial>
      <origin
        xyz="-4.75473982408658E-09 0.0232499943871629 0.0364632446678755"
        rpy="0 0 0" />
      <mass
        value="0.0699581201554127" />
      <inertia
        ixx="3.15837289122154E-05"
        ixy="-8.60933097674758E-11"
        ixz="-3.46721157397413E-12"
        iyy="2.19759227755569E-05"
        iyz="-4.28889640805252E-12"
        izz="1.91147421418883E-05" />
    </inertial>
    <visual>
      <origin
        xyz="0 0 0"
        rpy="0 0 0" />
      <geometry>
        <mesh
          filename="../meshes/lowerleg_fl.STL" />
      </geometry>
      <material
        name="">
        <color
          rgba="0.792156862745098 0.819607843137255 0.933333333333333 1" />
      </material>
    </visual>
    <collision>
      <origin
        xyz="0 0 0"
        rpy="0 0 0" />
      <geometry>
        <mesh
          filename="../meshes/lowerleg_fl.STL" />
      </geometry>
    </collision>
  </link>
  <joint
    name="knee_fl"
    type="revolute">
    <origin
      xyz="0.039486 0 0.038287"
      rpy="0 -0.77368 3.1416" />
    <parent
      link="upperleg_fl" />
    <child
      link="lowerleg_fl" />
    <axis
      xyz="0 1 0" />
    <limit
      lower="-1.57"
      upper="1.57"
      effort="0"
      velocity="0" />
  </joint>
  <link
    name="upperleg_fr">
    <inertial>
      <origin
        xyz="0.024758 -0.02325 0.024007"
        rpy="0 0 0" />
      <mass
        value="0.060463" />
      <inertia
        ixx="1.6946E-05"
        ixy="-6.4589E-12"
        ixz="-2.434E-06"
        iyy="1.3106E-05"
        iyz="7.418E-12"
        izz="1.7096E-05" />
    </inertial>
    <visual>
      <origin
        xyz="0 0 0"
        rpy="0 0 0" />
      <geometry>
        <mesh
          filename="../meshes/upperleg_fr.STL" />
      </geometry>
      <material
        name="">
        <color
          rgba="0.79216 0.81961 0.93333 1" />
      </material>
    </visual>
    <collision>
      <origin
        xyz="0 0 0"
        rpy="0 0 0" />
      <geometry>
        <mesh
          filename="../meshes/upperleg_fr.STL" />
      </geometry>
    </collision>
  </link>
  <joint
    name="hip_fr"
    type="revolute">
    <origin
      xyz="0.72627 -1.2165 0.72616"
      rpy="-3.1416 0.79756 -3.1416" />
    <parent
      link="base_link" />
    <child
      link="upperleg_fr" />
    <axis
      xyz="0 1 0" />
    <limit
      lower="-1.57"
      upper="1.57"
      effort="0"
      velocity="0" />
  </joint>
  <link
    name="lowerleg_fr">
    <inertial>
      <origin
        xyz="-4.43033831842854E-09 0.0232499934913899 0.0364632446845141"
        rpy="0 0 0" />
      <mass
        value="0.0699581202170087" />
      <inertia
        ixx="3.15837289580559E-05"
        ixy="-8.61359053758981E-11"
        ixz="-3.21737673796386E-12"
        iyy="2.19759227196836E-05"
        iyz="-4.73466202448819E-12"
        izz="1.91147421860981E-05" />
    </inertial>
    <visual>
      <origin
        xyz="0 0 0"
        rpy="0 0 0" />
      <geometry>
        <mesh
          filename="../meshes/lowerleg_fr.STL" />
      </geometry>
      <material
        name="">
        <color
          rgba="0.792156862745098 0.819607843137255 0.933333333333333 1" />
      </material>
    </visual>
    <collision>
      <origin
        xyz="0 0 0"
        rpy="0 0 0" />
      <geometry>
        <mesh
          filename="../meshes/lowerleg_fr.STL" />
      </geometry>
    </collision>
  </link>
  <joint
    name="knee_fr"
    type="revolute">
    <origin
      xyz="0.039486 0 0.038287"
      rpy="0 -0.81155 3.1416" />
    <parent
      link="upperleg_fr" />
    <child
      link="lowerleg_fr" />
    <axis
      xyz="0 1 0" />
    <limit
      lower="-1.57"
      upper="1.57"
      effort="0"
      velocity="0" />
  </joint>
  <link
    name="upperleg_bl">
    <inertial>
      <origin
        xyz="-0.00976295271731775 0.0232501900245516 0.0342534207407755"
        rpy="0 0 0" />
      <mass
        value="0.057335271066792" />
      <inertia
        ixx="1.76255413485992E-05"
        ixy="-5.41152248744027E-13"
        ixz="1.28237016851058E-06"
        iyy="1.2063396549517E-05"
        iyz="1.0696653020031E-11"
        izz="1.34257039052371E-05" />
    </inertial>
    <visual>
      <origin
        xyz="0 0 0"
        rpy="0 0 0" />
      <geometry>
        <mesh
          filename="../meshes/upperleg_bl.STL" />
      </geometry>
      <material
        name="">
        <color
          rgba="0.792156862745098 0.819607843137255 0.933333333333333 1" />
      </material>
    </visual>
    <collision>
      <origin
        xyz="0 0 0"
        rpy="0 0 0" />
      <geometry>
        <mesh
          filename="../meshes/upperleg_bl.STL" />
      </geometry>
    </collision>
  </link>
  <joint
    name="hip_bl"
    type="revolute">
    <origin
      xyz="0.55677 -1.3166 0.72616"
      rpy="3.1416 -0.26336 0" />
    <parent
      link="base_link" />
    <child
      link="upperleg_bl" />
    <axis
      xyz="0 1 0" />
    <limit
      lower="-1.57"
      upper="1.57"
      effort="0"
      velocity="0" />
  </joint>
  <link
    name="lowerleg_bl">
    <inertial>
      <origin
        xyz="-4.50047299427325E-09 0.0232499936818709 0.0364632446889597"
        rpy="0 0 0" />
      <mass
        value="0.0699581201747257" />
      <inertia
        ixx="3.15837289313372E-05"
        ixy="-8.61319622447907E-11"
        ixz="-3.27432434983183E-12"
        iyy="2.19759227157828E-05"
        iyz="-4.63160439353435E-12"
        izz="1.91147421677487E-05" />
    </inertial>
    <visual>
      <origin
        xyz="0 0 0"
        rpy="0 0 0" />
      <geometry>
        <mesh
          filename="../meshes/lowerleg_bl.STL" />
      </geometry>
      <material
        name="">
        <color
          rgba="0.792156862745098 0.819607843137255 0.933333333333333 1" />
      </material>
    </visual>
    <collision>
      <origin
        xyz="0 0 0"
        rpy="0 0 0" />
      <geometry>
        <mesh
          filename="../meshes/lowerleg_bl.STL" />
      </geometry>
    </collision>
  </link>
  <joint
    name="knee_bl"
    type="revolute">
    <origin
      xyz="-0.015108 0 0.052884"
      rpy="0 -0.27249 0" />
    <parent
      link="upperleg_bl" />
    <child
      link="lowerleg_bl" />
    <axis
      xyz="0 1 0" />
    <limit
      lower="-1.57"
      upper="1.57"
      effort="0"
      velocity="0" />
  </joint>
  <link
    name="upperleg_br">
    <inertial>
      <origin
        xyz="-0.00976295260659155 0.0232501900069702 0.0342534203947121"
        rpy="0 0 0" />
      <mass
        value="0.0573352716458123" />
      <inertia
        ixx="1.76255417264354E-05"
        ixy="-5.20102424970887E-13"
        ixz="1.28237020513566E-06"
        iyy="1.20633967746612E-05"
        iyz="1.07104648069426E-11"
        izz="1.34257040994798E-05" />
    </inertial>
    <visual>
      <origin
        xyz="0 0 0"
        rpy="0 0 0" />
      <geometry>
        <mesh
          filename="../meshes/upperleg_br.STL" />
      </geometry>
      <material
        name="">
        <color
          rgba="0.792156862745098 0.819607843137255 0.933333333333333 1" />
      </material>
    </visual>
    <collision>
      <origin
        xyz="0 0 0"
        rpy="0 0 0" />
      <geometry>
        <mesh
          filename="../meshes/upperleg_br.STL" />
      </geometry>
    </collision>
  </link>
  <joint
    name="hip_br"
    type="revolute">
    <origin
      xyz="0.55677 -1.2016 0.72616"
      rpy="-3.1416 -0.27684 0" />
    <parent
      link="base_link" />
    <child
      link="upperleg_br" />
    <axis
      xyz="0 1 0" />
    <limit
      lower="-1.57"
      upper="1.57"
      effort="0"
      velocity="0" />
  </joint>
  <link
    name="lowerleg_br">
    <inertial>
      <origin
        xyz="-4.47946635340202E-09 0.0232499936248449 0.0364632446874792"
        rpy="0 0 0" />
      <mass
        value="0.0699581201944018" />
      <inertia
        ixx="3.15837289412452E-05"
        ixy="-8.6133189217402E-11"
        ixz="-3.25734301185056E-12"
        iyy="2.19759227174298E-05"
        iyz="-4.66253146666271E-12"
        izz="1.91147421751615E-05" />
    </inertial>
    <visual>
      <origin
        xyz="0 0 0"
        rpy="0 0 0" />
      <geometry>
        <mesh
          filename="../meshes/lowerleg_br.STL" />
      </geometry>
      <material
        name="">
        <color
          rgba="0.792156862745098 0.819607843137255 0.933333333333333 1" />
      </material>
    </visual>
    <collision>
      <origin
        xyz="0 0 0"
        rpy="0 0 0" />
      <geometry>
        <mesh
          filename="../meshes/lowerleg_br.STL" />
      </geometry>
    </collision>
  </link>
  <joint
    name="knee_br"
    type="revolute">
    <origin
      xyz="-0.015108 0 0.052884"
      rpy="0 -0.29892 0" />
    <parent
      link="upperleg_br" />
    <child
      link="lowerleg_br" />
    <axis
      xyz="0 1 0" />
    <limit
      lower="-1.57"
      upper="1.57"
      effort="0"
      velocity="0" />
  </joint>
</robot>