<?xml version="1.0" encoding="utf-8"?>
<!-- This URDF was automatically created by SolidWorks to URDF Exporter! Originally created by Stephen Brawner (brawner@gmail.com) 
     Commit Version: 1.6.0-4-g7f85cfe  Build Version: 1.6.7995.38578
     For more information, please see http://wiki.ros.org/sw_urdf_exporter -->
<robot
  name="cat_model.SLDASM">
  <link
    name="base_link">
    <inertial>
      <origin
        xyz="-8.0754E-19 0.00127 -8.6736E-19"
        rpy="0 0 0" />
      <mass
        value="0.00043835" />
      <inertia
        ixx="6.1275E-09"
        ixy="1.9803E-26"
        ixz="-8.1778E-25"
        iyy="1.1784E-08"
        iyz="0"
        izz="6.1275E-09" />
    </inertial>
    <visual>
      <origin
        xyz="0 0 0"
        rpy="0 0 0" />
      <geometry>
        <mesh
          filename="base_link.STL" />
      </geometry>
      <material
        name="">
        <color
          rgba="1 1 1 0.35" />
      </material>
    </visual>
    <collision>
      <origin
        xyz="0 0 0"
        rpy="0 0 0" />
      <geometry>
        <mesh
          filename="base_link.STL" />
      </geometry>
    </collision>
  </link>
  <link
    name="body">
    <inertial>
      <origin
        xyz="0.054702 0.046613 0.11825"
        rpy="0 0 0" />
      <mass
        value="1.1876" />
      <inertia
        ixx="0.0018536"
        ixy="0.00010163"
        ixz="-1.9771E-07"
        iyy="0.0071097"
        iyz="-4.4693E-07"
        izz="0.0062115" />
    </inertial>
    <visual>
      <origin
        xyz="0 0 0"
        rpy="0 0 0" />
      <geometry>
        <mesh
          filename="body.STL" />
      </geometry>
      <material
        name="">
        <color
          rgba="0.79216 0.81961 0.93333 1" />
      </material>
    </visual>
    <collision>
      <origin
        xyz="0 0 0"
        rpy="0 0 0" />
      <geometry>
        <mesh
          filename="body.STL" />
      </geometry>
    </collision>
  </link>
  <joint
    name="base_joint"
    type="fixed">
    <origin
      xyz="-0.04859 0.11829 0.013453"
      rpy="1.5708 0 0" />
    <parent
      link="base_link" />
    <child
      link="body" />
    <axis
      xyz="0 0 0" />
  </joint>
  <link
    name="upperleg_fl">
    <inertial>
      <origin
        xyz="0.024758 -0.02325 0.024007"
        rpy="0 0 0" />
      <mass
        value="0.064696" />
      <inertia
        ixx="1.8133E-05"
        ixy="-6.9112E-12"
        ixz="-2.6043E-06"
        iyy="1.4023E-05"
        iyz="7.9351E-12"
        izz="1.8293E-05" />
    </inertial>
    <visual>
      <origin
        xyz="0 0 0"
        rpy="0 0 0" />
      <geometry>
        <mesh
          filename="upperleg_fl.STL" />
      </geometry>
      <material
        name="">
        <color
          rgba="0.79216 0.81961 0.93333 1" />
      </material>
    </visual>
    <collision>
      <origin
        xyz="0 0 0"
        rpy="0 0 0" />
      <geometry>
        <mesh
          filename="upperleg_fl.STL" />
      </geometry>
    </collision>
  </link>
  <joint
    name="hip_fl"
    type="revolute">
    <origin
      xyz="0.13334 -0.048413 0.13763"
      rpy="-1.5708 0 -2.3382" />
    <parent
      link="body" />
    <child
      link="upperleg_fl" />
    <axis
      xyz="0 1 0" />
    <limit
      lower="-1.57"
      upper="1.57"
      effort="0"
      velocity="0" />
  </joint>
  <link
    name="lowerleg_fl">
    <inertial>
      <origin
        xyz="-4.9993E-09 -0.02325 0.036463"
        rpy="0 0 0" />
      <mass
        value="0.074855" />
      <inertia
        ixx="3.3795E-05"
        ixy="-9.212E-11"
        ixz="-3.9082E-12"
        iyy="2.3514E-05"
        iyz="-4.2372E-12"
        izz="2.0453E-05" />
    </inertial>
    <visual>
      <origin
        xyz="0 0 0"
        rpy="0 0 0" />
      <geometry>
        <mesh
          filename="lowerleg_fl.STL" />
      </geometry>
      <material
        name="">
        <color
          rgba="0.79216 0.81961 0.93333 1" />
      </material>
    </visual>
    <collision>
      <origin
        xyz="0 0 0"
        rpy="0 0 0" />
      <geometry>
        <mesh
          filename="lowerleg_fl.STL" />
      </geometry>
    </collision>
  </link>
  <joint
    name="knee_fl"
    type="revolute">
    <origin
      xyz="0.039486 0 0.038287"
      rpy="0 0.81927 0" />
    <parent
      link="upperleg_fl" />
    <child
      link="lowerleg_fl" />
    <axis
      xyz="0 1 0" />
    <limit
      lower="-1.57"
      upper="1.57"
      effort="0"
      velocity="0" />
  </joint>
  <link
    name="upperleg_fr">
    <inertial>
      <origin
        xyz="0.024758 0.02325 0.024007"
        rpy="0 0 0" />
      <mass
        value="0.064696" />
      <inertia
        ixx="1.8133E-05"
        ixy="-6.9111E-12"
        ixz="-2.6043E-06"
        iyy="1.4023E-05"
        iyz="7.9349E-12"
        izz="1.8293E-05" />
    </inertial>
    <visual>
      <origin
        xyz="0 0 0"
        rpy="0 0 0" />
      <geometry>
        <mesh
          filename="upperleg_fr.STL" />
      </geometry>
      <material
        name="">
        <color
          rgba="0.79216 0.81961 0.93333 1" />
      </material>
    </visual>
    <collision>
      <origin
        xyz="0 0 0"
        rpy="0 0 0" />
      <geometry>
        <mesh
          filename="upperleg_fr.STL" />
      </geometry>
    </collision>
  </link>
  <joint
    name="hip_fr"
    type="revolute">
    <origin
      xyz="0.13334 -0.048413 0.052443"
      rpy="1.5708 0 -0.80381" />
    <parent
      link="body" />
    <child
      link="upperleg_fr" />
    <axis
      xyz="0 1 0" />
    <limit
      lower="-1.57"
      upper="1.57"
      effort="0"
      velocity="0" />
  </joint>
  <link
    name="lowerleg_fr">
    <inertial>
      <origin
        xyz="-4.552E-09 0.02325 0.036463"
        rpy="0 0 0" />
      <mass
        value="0.074855" />
      <inertia
        ixx="3.3795E-05"
        ixy="-9.2158E-11"
        ixz="-3.5484E-12"
        iyy="2.3514E-05"
        iyz="-4.8747E-12"
        izz="2.0453E-05" />
    </inertial>
    <visual>
      <origin
        xyz="0 0 0"
        rpy="0 0 0" />
      <geometry>
        <mesh
          filename="lowerleg_fr.STL" />
      </geometry>
      <material
        name="">
        <color
          rgba="0.79216 0.81961 0.93333 1" />
      </material>
    </visual>
    <collision>
      <origin
        xyz="0 0 0"
        rpy="0 0 0" />
      <geometry>
        <mesh
          filename="lowerleg_fr.STL" />
      </geometry>
    </collision>
  </link>
  <joint
    name="knee_fr"
    type="revolute">
    <origin
      xyz="0.039486 0 0.038287"
      rpy="0 0.79665 0" />
    <parent
      link="upperleg_fr" />
    <child
      link="lowerleg_fr" />
    <axis
      xyz="0 1 0" />
    <limit
      lower="-1.57"
      upper="1.57"
      effort="0"
      velocity="0" />
  </joint>
  <link
    name="upperleg_bl">
    <inertial>
      <origin
        xyz="-0.009763 0.02325 0.034253"
        rpy="0 0 0" />
      <mass
        value="0.061349" />
      <inertia
        ixx="1.8859E-05"
        ixy="-5.5679E-13"
        ixz="1.3721E-06"
        iyy="1.2908E-05"
        iyz="1.1462E-11"
        izz="1.4366E-05" />
    </inertial>
    <visual>
      <origin
        xyz="0 0 0"
        rpy="0 0 0" />
      <geometry>
        <mesh
          filename="upperleg_bl.STL" />
      </geometry>
      <material
        name="">
        <color
          rgba="0.79216 0.81961 0.93333 1" />
      </material>
    </visual>
    <collision>
      <origin
        xyz="0 0 0"
        rpy="0 0 0" />
      <geometry>
        <mesh
          filename="upperleg_bl.STL" />
      </geometry>
    </collision>
  </link>
  <joint
    name="hip_bl"
    type="revolute">
    <origin
      xyz="-0.036159 -0.048413 0.15254"
      rpy="1.5708 0 0.28437" />
    <parent
      link="body" />
    <child
      link="upperleg_bl" />
    <axis
      xyz="0 1 0" />
    <limit
      lower="-1.57"
      upper="1.57"
      effort="0"
      velocity="0" />
  </joint>
  <link
    name="lowerleg_bl">
    <inertial>
      <origin
        xyz="-4.9664E-09 -0.02325 0.036463"
        rpy="0 0 0" />
      <mass
        value="0.074855" />
      <inertia
        ixx="3.3795E-05"
        ixy="-9.2123E-11"
        ixz="-3.8796E-12"
        iyy="2.3514E-05"
        iyz="-4.289E-12"
        izz="2.0453E-05" />
    </inertial>
    <visual>
      <origin
        xyz="0 0 0"
        rpy="0 0 0" />
      <geometry>
        <mesh
          filename="lowerleg_bl.STL" />
      </geometry>
      <material
        name="">
        <color
          rgba="0.79216 0.81961 0.93333 1" />
      </material>
    </visual>
    <collision>
      <origin
        xyz="0 0 0"
        rpy="0 0 0" />
      <geometry>
        <mesh
          filename="lowerleg_bl.STL" />
      </geometry>
    </collision>
  </link>
  <joint
    name="knee_bl"
    type="revolute">
    <origin
      xyz="-0.015108 0 0.052884"
      rpy="0 0.30565 -3.1416" />
    <parent
      link="upperleg_bl" />
    <child
      link="lowerleg_bl" />
    <axis
      xyz="0 1 0" />
    <limit
      lower="-1.57"
      upper="1.57"
      effort="0"
      velocity="0" />
  </joint>
  <link
    name="upperleg_br">
    <inertial>
      <origin
        xyz="-0.009763 -0.02325 0.034253"
        rpy="0 0 0" />
      <mass
        value="0.061349" />
      <inertia
        ixx="1.8859E-05"
        ixy="-5.5571E-13"
        ixz="1.3721E-06"
        iyy="1.2908E-05"
        iyz="1.146E-11"
        izz="1.4366E-05" />
    </inertial>
    <visual>
      <origin
        xyz="0 0 0"
        rpy="0 0 0" />
      <geometry>
        <mesh
          filename="upperleg_br.STL" />
      </geometry>
      <material
        name="">
        <color
          rgba="0.79216 0.81961 0.93333 1" />
      </material>
    </visual>
    <collision>
      <origin
        xyz="0 0 0"
        rpy="0 0 0" />
      <geometry>
        <mesh
          filename="upperleg_br.STL" />
      </geometry>
    </collision>
  </link>
  <joint
    name="hip_br"
    type="revolute">
    <origin
      xyz="-0.036159 -0.048413 0.037536"
      rpy="-1.5708 0 2.8638" />
    <parent
      link="body" />
    <child
      link="upperleg_br" />
    <axis
      xyz="0 1 0" />
    <limit
      lower="-1.57"
      upper="1.57"
      effort="0"
      velocity="0" />
  </joint>
  <link
    name="lowerleg_br">
    <inertial>
      <origin
        xyz="-4.7344E-09 0.02325 0.036463"
        rpy="0 0 0" />
      <mass
        value="0.074855" />
      <inertia
        ixx="3.3795E-05"
        ixy="-9.2121E-11"
        ixz="-3.6922E-12"
        iyy="2.3514E-05"
        iyz="-4.621E-12"
        izz="2.0453E-05" />
    </inertial>
    <visual>
      <origin
        xyz="0 0 0"
        rpy="0 0 0" />
      <geometry>
        <mesh
          filename="lowerleg_br.STL" />
      </geometry>
      <material
        name="">
        <color
          rgba="0.79216 0.81961 0.93333 1" />
      </material>
    </visual>
    <collision>
      <origin
        xyz="0 0 0"
        rpy="0 0 0" />
      <geometry>
        <mesh
          filename="lowerleg_br.STL" />
      </geometry>
    </collision>
  </link>
  <joint
    name="knee_br"
    type="revolute">
    <origin
      xyz="-0.015108 0 0.052884"
      rpy="0 0.27827 -3.1416" />
    <parent
      link="upperleg_br" />
    <child
      link="lowerleg_br" />
    <axis
      xyz="0 1 0" />
    <limit
      lower="-1.57"
      upper="1.57"
      effort="0"
      velocity="0" />
  </joint>
</robot>